Workbook
Name Liste_Familles_COSWIN: 'Ne pas modifier'!$E$1:$E$805

Sheet Synthèse contrôle IA
A1: CONTROLE COSWIN — REPRISE DU 07/10/2026
A2: Indicateur | B2: Classe A | C2: Classe B | D2: Total | E2: Définition / périmètre | G2: Paramètre | H2: Valeur | I2: Unité et source
A3: Articles présents | B3: =COUNTIF('Classe A - Article spécifique'!D3:D517,"<>") -> 515 | C3: =COUNTIF('Classe B - Article générique'!D3:D48,"<>") -> 46 | D3: =SUM(B3:C3) -> 561 | E3: Référence originale renseignée ; emplacements préremplis sans référence exclus. | G3: Champs confirmés indépendants | H3: 4 | I3: nombre — cahier de contrôle
A4: Articles déjà codés — exclus | B4: =COUNTIFS('Classe A - Article spécifique'!D3:D517,"<>",'Classe A - Article spécifique'!R3:R517,"<>") -> 409 | C4: =COUNTIFS('Classe B - Article générique'!D3:D48,"<>",'Classe B - Article générique'!R3:R48,"<>") -> 29 | D4: =SUM(B4:C4) -> 438 | E4: Code Article non vide, y compris OBSOLETE ; aucun enrichissement ni recherche. | G4: Limite désignation | H4: 100 | I4: caractères — cahier de contrôle
A5: Articles contrôlés | B5: =COUNTIFS('Classe A - Article spécifique'!D3:D517,"<>",'Classe A - Article spécifique'!R3:R517,"") -> 106 | C5: =COUNTIFS('Classe B - Article générique'!D3:D48,"<>",'Classe B - Article générique'!R3:R48,"") -> 17 | D5: =SUM(B5:C5) -> 123 | E5: Référence renseignée et Code Article vide ; contrôle depuis zéro. | G5: Limite machine | H5: 20 | I5: caractères — cahier de contrôle
A6: Références constructeur confirmées | B6: =COUNTIFS('Classe A - Article spécifique'!R3:R517,"",'Classe A - Article spécifique'!D3:D517,"<>",'Classe A - Article spécifique'!W3:W517,"<>") -> 25 | C6: =COUNTIFS('Classe B - Article générique'!R3:R48,"",'Classe B - Article générique'!D3:D48,"<>",'Classe B - Article générique'!U3:U48,"<>") -> 7 | D6: =SUM(B6:C6) -> 32 | E6: Champ confirmé non vide ; existence du type peut être confirmée sans valider toutes ses options. | G6: Seuil dominante | H6: 0.3 | I6: % — cahier de contrôle
A7: Marques confirmées | B7: =COUNTIFS('Classe A - Article spécifique'!R3:R517,"",'Classe A - Article spécifique'!D3:D517,"<>",'Classe A - Article spécifique'!X3:X517,"<>") -> 22 | C7: =COUNTIFS('Classe B - Article générique'!R3:R48,"",'Classe B - Article générique'!D3:D48,"<>",'Classe B - Article générique'!V3:V48,"<>") -> 8 | D7: =SUM(B7:C7) -> 30 | E7: Fabricant de la référence prouvé ; identité de société ou série seule ne remplit pas ce champ. | G7: Date contrôle | H7: 46302 | I7: date — demande de cette exécution
A8: Référence ET marque confirmées | B8: =COUNTIFS('Classe A - Article spécifique'!R3:R517,"",'Classe A - Article spécifique'!D3:D517,"<>",'Classe A - Article spécifique'!W3:W517,"<>",'Classe A - Article spécifique'!X3:X517,"<>") -> 21 | C8: =COUNTIFS('Classe B - Article générique'!R3:R48,"",'Classe B - Article générique'!D3:D48,"<>",'Classe B - Article générique'!U3:U48,"<>",'Classe B - Article générique'!V3:V48,"<>") -> 7 | D8: =SUM(B8:C8) -> 28 | E8: Deux champs confirmés simultanément ; seuls les articles non codés.
A9: Fournisseurs saisis confirmés | B9: =COUNTIFS('Classe A - Article spécifique'!R3:R517,"",'Classe A - Article spécifique'!D3:D517,"<>",'Classe A - Article spécifique'!Y3:Y517,"<>") -> 96 | C9: =COUNTIFS('Classe B - Article générique'!R3:R48,"",'Classe B - Article générique'!D3:D48,"<>",'Classe B - Article générique'!W3:W48,"<>") -> 17 | D9: =SUM(B9:C9) -> 113 | E9: Identité du fournisseur saisi vérifiée, sans substitution par un autre vendeur.
A10: Références fournisseur confirmées | B10: =COUNTIFS('Classe A - Article spécifique'!R3:R517,"",'Classe A - Article spécifique'!D3:D517,"<>",'Classe A - Article spécifique'!Z3:Z517,"<>") -> 8 | C10: =COUNTIFS('Classe B - Article générique'!R3:R48,"",'Classe B - Article générique'!D3:D48,"<>",'Classe B - Article générique'!X3:X48,"<>") -> 8 | D10: =SUM(B10:C10) -> 16 | E10: Code effectivement documenté chez le fournisseur saisi.
A11: Valeurs non confirmées — 4 champs | B11: =B5*$H$3-SUM(B6:B7,B9:B10) -> 273 | C11: =C5*$H$3-SUM(C6:C7,C9:C10) -> 28 | D11: =SUM(B11:C11) -> 301 | E11: Cellules vides parmi référence constructeur, marque, fournisseur, référence fournisseur, sur contrôlés uniquement.
A12: Articles avec au moins 1 champ non confirmé | B12: =B5-COUNTIFS('Classe A - Article spécifique'!R3:R517,"",'Classe A - Article spécifique'!D3:D517,"<>",'Classe A - Article spécifique'!W3:W517,"<>",'Classe A - Article spécifique'!X3:X517,"<>",'Classe A - Article spécifique'!Y3:Y517,"<>",'Classe A - Article spécifique'!Z3:Z517,"<>") -> 101 | C12: =C5-COUNTIFS('Classe B - Article générique'!R3:R48,"",'Classe B - Article générique'!D3:D48,"<>",'Classe B - Article générique'!U3:U48,"<>",'Classe B - Article générique'!V3:V48,"<>",'Classe B - Article générique'!W3:W48,"<>",'Classe B - Article générique'!X3:X48,"<>") -> 11 | D12: =SUM(B12:C12) -> 112 | E12: Articles contrôlés moins articles possédant les 4 champs confirmés.
A13: Pièces explicitement sur plan | B13: =COUNTIF('Classe A - Article spécifique'!AP3:AP517,"Non applicable") -> 1 | C13: =COUNTIF('Classe B - Article générique'!AN3:AN48,"Non applicable") -> 0 | D13: =SUM(B13:C13) -> 1 | E13: Indice Non applicable ; le plan fait foi, absence catalogue normale.
A14: Articles avec au moins 1 photo | B14: {=SUMPRODUCT(--('Classe A - Article spécifique'!R3:R517=""),--((('Classe A - Article spécifique'!AI3:AI517<>"")+('Classe A - Article spécifique'!AJ3:AJ517<>"")+('Classe A - Article spécifique'!AK3:AK517<>""))>0))} -> 0 | C14: {=SUMPRODUCT(--('Classe B - Article générique'!R3:R48=""),--((('Classe B - Article générique'!AG3:AG48<>"")+('Classe B - Article générique'!AH3:AH48<>"")+('Classe B - Article générique'!AI3:AI48<>""))>0))} -> 0 | D14: =SUM(B14:C14) -> 0 | E14: Au moins une vraie image admissible dans les trois colonnes photo.
A15: TOTAL PHOTOS | B15: =COUNTIFS('Classe A - Article spécifique'!R3:R517,"",'Classe A - Article spécifique'!AI3:AI517,"http*")+COUNTIFS('Classe A - Article spécifique'!R3:R517,"",'Classe A - Article spécifique'!AJ3:AJ517,"http*")+COUNTIFS('Classe A - Article spécifique'!R3:R517,"",'Classe A - Article spécifique'!AK3:AK517,"http*") -> 0 | C15: =COUNTIFS('Classe B - Article générique'!R3:R48,"",'Classe B - Article générique'!AG3:AG48,"http*")+COUNTIFS('Classe B - Article générique'!R3:R48,"",'Classe B - Article générique'!AH3:AH48,"http*")+COUNTIFS('Classe B - Article générique'!R3:R48,"",'Classe B - Article générique'!AI3:AI48,"http*") -> 0 | D15: =SUM(B15:C15) -> 0 | E15: Nombre de liens image dans Photo produit 1/2/3 seulement ; fiches et pages exclus.
A16: Articles avec code(s) de base candidat(s) | B16: =COUNTIFS('Classe A - Article spécifique'!R3:R517,"",'Classe A - Article spécifique'!D3:D517,"<>",'Classe A - Article spécifique'!AH3:AH517,"<>") -> 6 | C16: =COUNTIFS('Classe B - Article générique'!R3:R48,"",'Classe B - Article générique'!D3:D48,"<>",'Classe B - Article générique'!AF3:AF48,"<>") -> 0 | D16: =SUM(B16:C16) -> 6 | E16: Correspondances normalisées, dédoublonnées par code ; pas un doublon certain par défaut.
A17: Codes distincts de base par demande | B17: =SUMIFS('Points à valider'!K3:K125,'Points à valider'!B3:B125,"Classe A - Article spécifique") -> 8 | C17: =SUMIFS('Points à valider'!K3:K125,'Points à valider'!B3:B125,"Classe B - Article générique") -> 0 | D17: =SUM(B17:C17) -> 8 | E17: Somme du nombre de codes distincts pour chaque demande ; aucune répétition fournisseur comptée.
A18: Doublons base à confirmer | B18: =COUNTIFS('Points à valider'!B3:B125,"Classe A - Article spécifique",'Points à valider'!L3:L125,"DOUBLON BASE A CONFIRMER") -> 4 | C18: =COUNTIFS('Points à valider'!B3:B125,"Classe B - Article générique",'Points à valider'!L3:L125,"DOUBLON BASE A CONFIRMER") -> 0 | D18: =SUM(B18:C18) -> 4 | E18: Référence/contexte compatibles ; validation du code existant nécessaire.
A19: Candidats ambigus base | B19: =COUNTIFS('Points à valider'!B3:B125,"Classe A - Article spécifique",'Points à valider'!L3:L125,"CANDIDAT AMBIGU BASE") -> 2 | C19: =COUNTIFS('Points à valider'!B3:B125,"Classe B - Article générique",'Points à valider'!L3:L125,"CANDIDAT AMBIGU BASE") -> 0 | D19: =SUM(B19:C19) -> 2 | E19: Dentures/dimensions ou variante non résolues ; ne pas fusionner automatiquement.
A20: Groupes de doublons internes potentiels | B20: =SUMIFS('Points à valider'!N3:N125,'Points à valider'!B3:B125,"Classe A - Article spécifique") -> 1 | C20: =SUMIFS('Points à valider'!N3:N125,'Points à valider'!B3:B125,"Classe B - Article générique") -> 1 | D20: =SUM(B20:C20) -> 2 | E20: Groupes croisant les deux classes. Les contributions A/B sont fractionnaires ; total = groupes distincts.
A21: Lignes dans un groupe interne potentiel | B21: =COUNTIFS('Points à valider'!B3:B125,"Classe A - Article spécifique",'Points à valider'!M3:M125,"<>") -> 2 | C21: =COUNTIFS('Points à valider'!B3:B125,"Classe B - Article générique",'Points à valider'!M3:M125,"<>") -> 2 | D21: =SUM(B21:C21) -> 4 | E21: Lignes non codées uniquement ; contextes conservés, pas de fusion de références.
A22: Désignations IA 1 renseignées | B22: =COUNTIFS('Classe A - Article spécifique'!R3:R517,"",'Classe A - Article spécifique'!D3:D517,"<>",'Classe A - Article spécifique'!AB3:AB517,"<>") -> 15 | C22: =COUNTIFS('Classe B - Article générique'!R3:R48,"",'Classe B - Article générique'!D3:D48,"<>",'Classe B - Article générique'!Z3:Z48,"<>") -> 6 | D22: =SUM(B22:C22) -> 21 | E22: Seulement un libellé officiel constructeur de la référence effectivement prouvée.
A23: Désignations IA 2 renseignées | B23: =COUNTIFS('Classe A - Article spécifique'!R3:R517,"",'Classe A - Article spécifique'!D3:D517,"<>",'Classe A - Article spécifique'!AD3:AD517,"<>") -> 106 | C23: =COUNTIFS('Classe B - Article générique'!R3:R48,"",'Classe B - Article générique'!D3:D48,"<>",'Classe B - Article générique'!AB3:AB48,"<>") -> 17 | D23: =SUM(B23:C23) -> 123 | E23: Termes sourcés/base contextualisée, ou proposition transparente ARTICLE A IDENTIFIER.
A24: Désignations algorithme renseignées | B24: =COUNTIFS('Classe A - Article spécifique'!R3:R517,"",'Classe A - Article spécifique'!D3:D517,"<>",'Classe A - Article spécifique'!AF3:AF517,"<>") -> 106 | C24: =COUNTIFS('Classe B - Article générique'!R3:R48,"",'Classe B - Article générique'!D3:D48,"<>",'Classe B - Article générique'!AD3:AD48,"<>") -> 17 | D24: =SUM(B24:C24) -> 123 | E24: Saisie d origine uniquement ; pas une validation fabricant.
A25: Écarts de contenu original observés | B25: ='Notes et sources'!B63 -> 0 | C25: ='Notes et sources'!B64 -> 0 | D25: =SUM(B25:C25,'Notes et sources'!B62) -> 0 | E25: Comparaison intégrale des cellules/formules originales et du référentiel ; conversions de type séparées.
A26: Conversions de type des identifiants | B26: ='Notes et sources'!B66 -> 165 | C26: ='Notes et sources'!B67 -> 10 | D26: =SUM(B26:C26) -> 175 | E26: Passage numérique/date -> TEXTE dans les trois colonnes originales ; aucune correction de contenu.
A27: Erreurs dans les nouvelles colonnes | B27: {=SUMPRODUCT(--ISERROR('Classe A - Article spécifique'!W3:AU517))} -> 0 | C27: {=SUMPRODUCT(--ISERROR('Classe B - Article générique'!U3:AS48))} -> 0 | D27: =SUM(B27:C27) -> 0 | E27: Contrôle de tous les résultats des colonnes ajoutées, sans masquer les erreurs.
A28: Erreur d origine connue préservée | B28: =COUNTIF('Classe A - Article spécifique'!F3:G1100,"#REF!") -> 0 | C28: =IF(ISERROR('Classe B - Article générique'!F91),1,0) -> 1 | D28: =SUM(B28:C28) -> 1 | E28: F91 vérifiée en erreur dans la Classe B ; audit intégral des autres résultats originaux sans autre erreur. G48 calculée 0 est signalée séparément.
A29: Élevé | B29: =COUNTIF('Classe A - Article spécifique'!AP3:AP517,"Élevé") -> 14 | C29: =COUNTIF('Classe B - Article générique'!AN3:AN48,"Élevé") -> 6 | D29: =SUM(B29:C29) -> 20 | E29: Référence constructeur exacte et caractéristiques concordantes.
A30: Moyen | B30: =COUNTIF('Classe A - Article spécifique'!AP3:AP517,"Moyen") -> 11 | C30: =COUNTIF('Classe B - Article générique'!AN3:AN48,"Moyen") -> 3 | D30: =SUM(B30:C30) -> 14 | E30: Preuve distributeur/devis ou petit écart ; portée expliquée.
A31: Faible | B31: =COUNTIF('Classe A - Article spécifique'!AP3:AP517,"Faible") -> 80 | C31: =COUNTIF('Classe B - Article générique'!AN3:AN48,"Faible") -> 8 | D31: =SUM(B31:C31) -> 88 | E31: Preuve insuffisante, configuration non confirmée ou contradiction.
A32: Non applicable | B32: =COUNTIF('Classe A - Article spécifique'!AP3:AP517,"Non applicable") -> 1 | C32: =COUNTIF('Classe B - Article générique'!AN3:AN48,"Non applicable") -> 0 | D32: =SUM(B32:C32) -> 1 | E32: Plan explicitement demandé ; pas de référence catalogue attendue.
A35: Lecture et décisions
A36: Exclusion | E36: Les propositions ne modifient aucune saisie originale. Les 438 lignes déjà codées n ont que leur statut d exclusion dans les ajouts.
A37: Confirmations | E37: Les identités de fournisseurs peuvent être vérifiées même si la référence fournisseur reste inconnue ; les quatre confirmations sont indépendantes.
A38: Désignations | E38: IA 1 = constructeur officiel exact ; IA 2 = termes vérifiés ou identification transparente ; algorithme = saisie seulement, sans validation technique.
A39: Traçabilité | E39: Points à valider et Sources vérifiées portent les localisations actuelles. 50 liens d origine conservés : 45 cliquables, 4 URLs longues sans cible courte reçue et 1 pièce jointe à accès refusé, conservées en texte.
A40: Photos / limites | E40: Limites : aucune photo admissible obtenue ; absence normale pour plan, pièces propriétaires et confections. Recherche d images dédiée indisponible dans l organisation.
A41: Erreurs source | E41: Erreurs originales préservées : Classe B F91 =LEN(#REF!) ; G48 =UPPER(F48), avec F48 =LEN(G48), désignation calculée 0 inexploitable.
A42: Fidélité de copie | E42: Fidélité de copie : valeurs, formules, dates, listes et styles utiles reproduits. Anciens formats conditionnels à formules non reproductibles ; nuances/bordures complexes non garanties à l identique.
...

Sheet Classe A - Article spécifique
A1: Version du 31/08/2026​ | B1: A remplir par le demandeur | C1: A remplir par le demandeur | D1: A remplir par le demandeur | E1: A remplir par le demandeur | F1: Ne pas modifier | G1: A remplir par le demandeur | H1: A remplir par le demandeur (menu déroulant) | I1: A remplir par le demandeur | J1: A remplir par le demandeur | K1: A remplir par le demandeur | L1: A remplir par le demandeur | M1: A remplir par le demandeur | N1: A remplir par le demandeur | O1: A remplir par le demandeur | P1: A remplir par le demandeur (menu déroulant) | Q1: A remplir par le demandeur | R1: A remplir par la Cellule Référentielle | S1: A remplir par la Cellule Référentielle | T1: A remplir par la Cellule Référentielle | U1: A remplir par la Cellule Référentielle | V1: A remplir par le demandeur | W1: Ajouté par le contrôle automatique — les colonnes d'origine ne sont jamais modifiées
A2: Classe Article | B2: Demandeur | C2: Date Demande | D2: Référence Fabricant / Générique | E2: Marque | F2: Check long. Désign. | G2: Désignation | H2: Famille | I2: Spécifique pour machine | J2: Unité Stock | K2: Unité Commande | L2: Certificat d'alimentarité? | M2: Fournisseur (nom) | N2: Fournisseur (code) | O2: Référence Fournisseur | P2: Site | Q2: Remarques demandeur | R2: Code Article | S2: Date de création | T2: Remarque Cellule Référentielle | U2: BPC | V2: Remarque complémentaire demandeur | W2: Référence constructeur confirmée | X2: Marque confirmée | Y2: Fournisseur confirmé | Z2: Référence fournisseur confirmée | AA2: Statut réf. / marque | AB2: Désignation IA 1 (constructeur) | AC2: Justification IA 1 | AD2: Désignation IA 2 (variante base article) | AE2: Justification IA 2 | AF2: Désignation algorithme | AG2: Justification algorithme | AH2: Article déjà existant (base) | AI2: Photo produit 1 (lien) | AJ2: Photo produit 2 (lien) | AK2: Photo produit 3 (lien) | AL2: Niveau photo | AM2: Fiche technique (lien) | AN2: Page constructeur (lien) | AO2: Page distributeur (lien) | AP2: Indice de confiance | AQ2: Justification du contrôle | AR2: Famille corrigée | AS2: Contrôle famille | AT2: Spécifique machine corrigé | AU2: Contrôle machine
A3: A | B3: Simon DROULERS | C3: 46266 | D3: 1C486160 | E3: DONALDSON | F3: =LEN(G3) -> 34 | G3: ELEMENT DE FILTRATION MODELE S0600 | H3: 110101 AIR / VIDE : FILTRES | J3: EA | K3: EA | L3: NON | M3: ULTRAFILTER DONALDSON VIGNY FR 95 | N3: 14922 | P3: ESTREES | R3: 086943 | S3: 46275 | U3: TRUE | AA3: DEJA CREE - article code 086943, ligne non retraitee.
A4: A | B4: Dany BACOT | C4: 46266 | D4: DO-21414-5-01 | E4: ET PACK | F4: =LEN(G4) -> 67 | G4: CHAINE A TAQUET MONTAGE AVANT TRANSPORT DE WRAP ETC20 DO-21414-5-01 | H4: 200000 ARTICLES SPECIFIQUES | I4: ENCAISSEUSE B4 | J4: EA | K4: EA | L4: NON | M4: ET PACK | N4: 6914 | O4: DO-21414-5-01 | P4: ESTREES | Q4: Pièces détachées_20170309 | R4: 086937 | S4: 46274 | T4: La désignation est issue de quel document. J'ai besoin de la doc du constructeur / Liste nomenclature complete de la machine. / Famille constructeur ET PACK ? PAS D'ACCES AUX PJ - | U4: FALSE | V4: LA MACHINE POSSEDE DEUX LOT DE CHAINE A TAQUET AVANT ET ARRIERE DONT UN LOT EST DEJA CODIFIER 086470 ET 086590 VOIR CI-DESSOUS JEANNINE EST AU COURANT VOIR CD30425043 ET LA FAMILLE ET PACK N'A JAMAIS EXISTER ( J'AI VALIDER LES ACCES PIECES JOINTE LE02/09/2026) | AA4: DEJA CREE - article code 086937, ligne non retraitee.
A5: A | B5: Dany BACOT | C5: 46266 | D5: D0-21418-5-01 | E5: ET PACK | F5: =LEN(G5) -> 69 | G5: CHAINE A TAQUET MONTAGE ARRIERE TRANSPORT DE WRAP ETC20 D0-21418-5-01 | H5: 200000 ARTICLES SPECIFIQUES | I5: ENCAISSEUSE B4 | J5: EA | K5: EA | L5: NON | M5: ET PACK | N5: 6914 | O5: D0-21418-5-01 | P5: ESTREES | Q5: Pièces détachées_20170309 | R5: 086938 | S5: 46274 | T5: La désignation est issue de quel document. J'ai besoin de la doc du constructeur / Liste nomenclature complete de la machine. / Famille constructeur ET PACK ? PAS D'ACCES AUX PJ | U5: FALSE | AA5: DEJA CREE - article code 086938, ligne non retraitee.
A6: A | B6: Vincent DARTHOS | C6: 46266 | D6: A&K 0030B | E6: A&K | F6: =LEN(G6) -> 26 | G6: HEX NUT 3/4'-16UNF JAM NUT | H6: 200500 A&K | I6: Effeuilleuse A&K | J6: EA | K6: EA | L6: NON | M6: FEMIA | N6: 597400 | P6: BORDERES | R6: 086881 | S6: 46268 | U6: TRUE | V6: Merci ! | AA6: DEJA CREE - article code 086881, ligne non retraitee.
A7: A | B7: Simon DROULERS | C7: 46266 | D7: 2TLA020051R5401 | E7: ABB | F7: =LEN(G7) -> 78 | G7: CAPTEUR DE SECURITE MAGNETIQUE ADAM SIGNAUX OSSD 24 VDC CONNECTEUR M12 SN 15MM | J7: EA | K7: EA | L7: NON | M7: SONEPAR FRANCE DISTRIBUTION-SFD NORD | N7: 151146 | P7: ESTREES | Q7: Il manque la famille des detecteurs de sécurité | R7: 086856 | T7: Doublon avec l'article 086856 (CAPTEUR DE SECURITE SANS CONTACT ADAM C OSSD INFO M12-5 24VDC). Demande non creee. | U7: FALSE | V7: Normal j'ai notifier une demande d'augmentation de stock dans le dossier | AA7: DEJA CREE - article code 086856, ligne non retraitee.
A8: A | B8: Simon DROULERS | C8: 01/09/2026 | D8: 2TLA020046R0801 | E8: ABB | F8: =LEN(G8) -> 78 | G8: RECEPTEUR ACTIONNEUR MAGNETIQUE DE SECURITE EVA CODE POUR CAPTEUR ADAM SN 15MM | J8: EA | K8: EA | L8: NON | M8: SONEPAR FRANCE DISTRIBUTION-SFD NORD | N8: 151146 | P8: ESTREES | Q8: Il manque la famille des detecteurs de sécurité | R8: 082107 | T8: Doublon avec l'article 082107 (CONTACT DE SECURITE PORTE EVA C GENERAL CODE). Demande non creee. | U8: FALSE | V8: Normal j'ai notifier une demande d'augmentation de stock dans le dossier | AA8: DEJA CREE - article code 082107, ligne non retraitee.
A9: A | B9: Simon DROULERS | C9: 01/09/2026 | D9: WI 421/16/45.31 | E9: Reovib | F9: =LEN(G9) -> 53 | G9: VIBRATEUR ELECTROMAGNETIQUE 660W 200V 3,3A 3000tr/min | H9: 150501 MOTEURS : MOTEURS A COURANT CONTINU | I9: Vibreur alim emboiteuse J/M | J9: EA | K9: EA | L9: NON | M9: SARL REOVARIAC EVRY FR 91 | N9: 150285 | P9: ESTREES | Q9: Image | T9: La gamme REOVIB WI 421 et la taille /16 sont confirmees sur la page constructeur officielle REO France et sur la fiche technique PDF REO, mais le suffixe de bobinage '/45.31' (variante tension/frequence) n'est reference dans aucune source publique et les valeurs electriques d'origine ne correspondent pas au tableau catalogue. | U9: FALSE | V9: La référence vient de la plaque moteur donc ça existe photo a l'appuie | Y9: REOVARIAC SARL | AA9: Série/gamme confirmée - configuration exacte non confirmée ; VALIDER - CHAMPS NON CONFIRMES | AC9: VIDE : aucun libellé officiel constructeur de la variante exacte n est confirmé. Une série, une société ou un libellé de distributeur ne remplace pas cette preuve. | AD9: AIMANT VIBRANT ELECTROMAGNETIQUE REOVIB WI421 - VARIANTE A VALIDER | AE9: Termes techniques issus exclusivement des sources vérifiées du 07/10/2026, reformulés selon l usage de la famille. Portée limitée à la série : cette proposition ne valide pas la variante ni les détails de saisie exclus des sources. Sources : REO AG — Aimant vibrant REOVIB WI421 — famille; REOVARIAC — Bienvenue sur le site de REOVARIAC | AF9: VIBRATEUR ELECTROMAGNETIQUE 660 W 200V 3,3A 3000TR/MIN | AG9: Saisie d origine uniquement, majuscules/espacement d unités et traduction usuelle sans ajout de caractéristiques. Nature source conservée sans substitution sémantique : 14 codes distincts de famille. Dominante MOTEUR : 9/14, soit 64.3% ; seuil d éligibilité 30 %, jamais une validation technique. | AL9: Aucune photo trouvée | AN9: =HYPERLINK("https://reo.fr/produit/aimant-vibrant-reovib-wi-421/","https://reo.fr/produit/aimant-vibrant-reovib-wi-421/") -> https://reo.fr/produit/aimant-vibrant-reovib-wi-421/ | AP9: Faible | AQ9: REO publie l’aimant vibrant WI421/16, non le suffixe /45.31 ni les valeurs de plaque saisies, et le site REOVARIAC vérifie le fournisseur REOVARIAC SARL sans code article exact; la portée reste donc série. La marque est laissée non confirmée : les sources identifient une société ou une série, pas le fabricant de la variante demandée. Photo : Les sorties web consultées ne fournissent aucune URL complète d'image éditeur admissible rattachée à cette référence; aucune recherche d'images dédiée effectuée. | AR9: 101500 CONVOYAGE VIBRANT | AS9: VALIDER - FAMILLE PROPOSEE : Aimant vibrant électromagnétique documenté ; la famille moteur à courant continu ne convient pas. | AT9: VIBREUR EMBOIT J M | AU9: VALIDER - ABREVIATION DE LA MACHINE SAISIE ; aucun équipement nouveau proposé.
A10: A | B10: Simon DROULERS | C10: 01/09/2026 | D10: SW 41 | E10: Reovib | F10: =LEN(G10) -> 49 | G10: CAPTEUR DE VIBRATION 600mV/g 10...60 Hz CABLE 10M | I10: Vibreur alim emboiteuse J/M | J10: EA | K10: EA | L10: NON | M10: SARL REOVARIAC EVRY FR 91 | N10: 150285 | P10: ESTREES | Q10: famille detection vibration ? | R10: 086885 | S10: 46268 | U10: TRUE | AA10: DEJA CREE - article code 086885, ligne non retraitee.
A11: A | B11: Simon DROULERS | C11: 01/09/2026 | D11: 411A-DOA-DM-DDAJ-1JB | E11: MAC Valves | F11: =LEN(G11) -> 48 | G11: DISTRIBUTEUR PNEUMATIQUE 5/2 24VDC 1,5 A 8,3 BAR | H11: 140500 PNEUMATIQUE : DISTRIBUTEURS | I11: Sertisseuse zacmi | J11: EA | K11: EA | L11: NON | M11: NOYER SAFIA DEXIS VENDIN LE VIEIL FR 62 | N11: 6248 | P11: ESTREES | R11: 086918 | S11: 46273 | U11: FALSE | AA11: DEJA CREE - article code 086918, ligne non retraitee.
A12: A | B12: Simon DROULERS | C12: 01/09/2026 | D12: BI50U-Q80-VP4X2-H1141 | E12: Turck Banner | F12: =LEN(G12) -> 87 | G12: CAPTEUR INDUCTIF RECTANGULAIRE PORTEE 50MM 10...65 VDC PNP CONTACT NO/NC CONNECTEUR M12 | H12: 105935 DETECTION : DETECTEURS INDUCTIFS PARALLELEPIPEDIQUES | I12: Sertisseuse zacmi | J12: EA | K12: EA | L12: NON | M12: ELECMATIC S.A.R.L | N12: 113787 | P12: ESTREES | R12: 086886 | S12: 46268 | U12: TRUE | AA12: DEJA CREE - article code 086886, ligne non retraitee.
A13: A | B13: Simon DROULERS | C13: 01/09/2026 | D13: TT5081 | E13: IFM | F13: =LEN(G13) -> 99 | G13: CAPTEUR DE TEMPERATURE PT100 INOX SONDE CYLIND Ø10 MM LONGUEUR 560 MM PLAGE -40 À +150°C CONNEC M12 | H13: 106235 MESURE ET REGULATION : MESURE DE LA TEMPERATURE | I13: Juteuse zacmi | J13: EA | K13: EA | L13: NON | M13: IFM ELECTRONIC LE BOURGET DU LAC FR 73 | N13: 5966 | P13: ESTREES | R13: 086814 | S13: 46266 | U13: TRUE | AA13: DEJA CREE - article code 086814, ligne non retraitee.
A14: A | B14: Simon DROULERS | C14: 01/09/2026 | D14: 54630 | E14: Murrelectronik | F14: =LEN(G14) -> 100 | G14: MODULE E/S DÉPORTÉ IP67 PROFINET, 8 DI/DO DIGITALES, 8 PORTS IO-LINK MASTER, CONNECTIQUE M12, 24 VDC | H14: 105245 AUTOMATISATION : ENTREES/SORTIES DISTRIBUEES | I14: Ligne J | J14: EA | K14: EA | L14: NON | M14: ELECMATIC S.A.R.L | N14: 113787 | P14: ESTREES | R14: 086893 | S14: 46272 | U14: TRUE | AA14: DEJA CREE - article code 086893, ligne non retraitee.
A15: A | B15: Simon DROULERS | C15: 01/09/2026 | D15: 4000-Hydrobar-EXTD(1,05m) 20-G7-G20-G39-G116-G225 | E15: Klay Instruments | F15: =LEN(G15) -> 98 | G15: TRANSMETTEUR PRESSION HYDROSTATIQUE IMMERGE MESURE NIVEAU LIQUIDE 4-20MA 24VDC INOX LONGUEUR 1,05M | H15: 106230 MESURE ET REGULATION : MESURE DE LA PRESSION | I15: Juteuse zacmi | J15: EA | K15: EA | L15: NON | M15: MESA THIAIS | N15: 74628 | P15: ESTREES | R15: 086895 | S15: 46272 | U15: TRUE | V15: ne pas mettre en stock supprimer de la ligne par fabricant car mauvais fonctionnement | AA15: DEJA CREE - article code 086895, ligne non retraitee.
A16: A | B16: Simon DROULERS | C16: 01/09/2026 | D16: RMA310 | E16: IFM | F16: =LEN(G16) -> 87 | G16: CODEUR ROTATIF ABSOLU MULTITOURS MAGNETIQUE I/O LINK ARBRE CREUX Ø12MM 24VDC IP68/IP69K | H16: 106201 MESURE ET REGULATION : CODEURS | I16: ? | J16: EA | K16: EA | L16: NON | M16: IFM ELECTRONIC LE BOURGET DU LAC FR 73 | N16: 5966 | P16: ESTREES | R16: 086887 | S16: 46269 | U16: TRUE | AA16: DEJA CREE - article code 086887, ligne non retraitee.
A17: A | B17: Simon DROULERS | C17: 01/09/2026 | D17: MFS368-8A-IP20 | E17: Reovib | F17: =LEN(G17) -> 81 | G17: VARIATEUR POUR VIBRATEUR ELECTROMAGNETIQUE 110...240VAC SORTIE 0...205VAC 8A IP20 | H17: 105830 CONVERTISSEURS : VARIATEURS DE VITESSE ALTERNATIF | I17: Vibreur alim emboiteuse J/M | J17: EA | K17: EA | L17: NON | M17: SARL REOVARIAC EVRY FR 91 | N17: 150285 | P17: ESTREES | R17: 086919 | S17: 46273 | U17: FALSE | AA17: DEJA CREE - article code 086919, ligne non retraitee.
A18: A | B18: Simon DROULERS | C18: 01/09/2026 | D18: 3SK1211-1BB40 | E18: SIEMENS | F18: =LEN(G18) -> 60 | G18: MODULE D'EXTENSION RELAI DE SECURITE 24 VDC SK1 4ES SECURITE | H18: 105755 CONTACTEURS ET RELAIS : RELAIS DE SECURITE | I18: J | J18: EA | K18: EA | L18: NON | M18: SONEPAR FRANCE DISTRIBUTION-SFD NORD | N18: 151146 | P18: ESTREES | R18: 086894 | S18: 46272 | U18: TRUE | AA18: DEJA CREE - article code 086894, ligne non retraitee.
A19: A | B19: Simon DROULERS | C19: 01/09/2026 | D19: 36103 000B | E19: WOHNER | F19: =LEN(G19) -> 99 | G19: DÉMARREUR MOTEUR HYBRIDE CONTACTEUR INVERSEUR FONCTION DE SÉCURITÉ SIL3 3 PÔLES 0,18-2,4 A RAIL DIN | H19: 105805 CONVERTISSEURS : DEMARREURS PROGRESSIFS | I19: J | J19: EA | K19: EA | L19: NON | M19: ELECMATIC S.A.R.L | N19: 113787 | P19: ESTREES | R19: 086898 | S19: 46272 | U19: TRUE | AA19: DEJA CREE - article code 086898, ligne non retraitee.
A20: A | B20: Simon DROULERS | C20: 01/09/2026 | D20: 36106 000B | E20: WOHNER | F20: =LEN(G20) -> 96 | G20: DÉMARREUR MOTEUR HYBRIDE CONTACTEUR INVERSEUR FONCTION DE SÉCURITÉ SIL3 3 PÔLES 1,5–9 A RAIL DIN | H20: 105805 CONVERTISSEURS : DEMARREURS PROGRESSIFS | I20: J | J20: EA | K20: EA | L20: NON | M20: ELECMATIC S.A.R.L | N20: 113787 | P20: ESTREES | R20: 086900 | S20: 46272 | U20: FALSE | AA20: DEJA CREE - article code 086900, ligne non retraitee.
A21: A | B21: Simon DROULERS | C21: 01/09/2026 | D21: PI2799 | E21: IFM | F21: =LEN(G21) -> 100 | G21: CAPTEUR DE PRESSION AFFLEUR I/O LINK -1..1 BAR 2STOR 1S ANA TEMP -25..125° CONNECTEUR M12 RACCORD G1 | H21: 106230 MESURE ET REGULATION : MESURE DE LA PRESSION | I21: Juteuse zacmi | J21: EA | K21: EA | L21: NON | M21: IFM ELECTRONIC LE BOURGET DU LAC FR 73 | N21: 5966 | P21: ESTREES | R21: 086888 | S21: 46269 | U21: FALSE | AA21: DEJA CREE - article code 086888, ligne non retraitee.
A22: A | B22: Simon DROULERS | C22: 01/09/2026 | D22: PL20S-11311.133013.G07020010000 | E22: Baumer | F22: =LEN(G22) -> 86 | G22: CAPTEUR DE NIVEAU SEUIL CAPACITIF I/O LINK PNP CONNECTEUR M12 G1/2 10-30VDC IP67/IP69K | H22: 106240 MESURE ET REGULATION : MESURE DE NIVEAU / DISTANCE | I22: Juteuse zacmi | J22: EA | K22: EA | L22: NON | M22: ELECMATIC S.A.R.L | N22: 113787 | P22: ESTREES | R22: 086929 | S22: 46273 | U22: TRUE | AA22: DEJA CREE - article code 086929, ligne non retraitee.
A23: A | B23: Simon DROULERS | C23: 01/09/2026 | D23: GG711S | E23: IFM | F23: =LEN(G23) -> 75 | G23: DETECTEUR DE SECURITE INDUCTIF M18 2OSSD PNP 24VDC SN 1..8MM CONNECTEUR M12 | I23: J | J23: EA | K23: EA | L23: NON | M23: IFM ELECTRONIC LE BOURGET DU LAC FR 73 | N23: 5966 | P23: ESTREES | Q23: pas de famille détecteur de sécurité | R23: 086889 | S23: 46269 | U23: TRUE | AA23: DEJA CREE - article code 086889, ligne non retraitee.
A24: A | B24: Simon DROULERS | C24: 01/09/2026 | D24: VCA 2 U4 F4 R1 SH | E24: KRACHT | F24: =LEN(G24) -> 74 | G24: DEBITMETRE VOLUMETRIQUE HYDRAULIQUE A ENGRENAGES AVEC CAPTEUR IMPULSIONNEL | H24: 106220 MESURE ET REGULATION : MESURE DE DEBIT | I24: J | J24: EA | K24: EA | L24: NON | P24: ESTREES | R24: 086928 | S24: 46273 | U24: FALSE | AA24: DEJA CREE - article code 086928, ligne non retraitee.
A25: A | B25: Simon DROULERS | C25: 01/09/2026 | D25: MPS-B330P-MJ52DA | E25: Allen Bradley | F25: =LEN(G25) -> 96 | G25: MOTEUR BRUSHLESS AC 460V 5000TR/MIN COUPLE 3,6 NM ARBRE CLAVETÉ Ø24MM CODEUR ABSOLU BOÎTIER INOX | H25: 150520 MOTEURS : MOTEURS BRUSHLESS | I25: J | J25: EA | K25: EA | L25: NON | P25: ESTREES | R25: 086953 | S25: 46279 | U25: FALSE | AA25: DEJA CREE - article code 086953, ligne non retraitee.
A26: A | B26: Simon DROULERS | C26: 01/09/2026 | D26: SR085IE-TT-02-08-T0302-V107 | E26: Kübler | F26: =LEN(G26) -> 88 | G26: COLLECTEUR TOURNANT SR085 ETHERNET INDUS 2 VOIES SIGNAUX 8 VOIES PUISSANCE MIXTE 10A/25A | H26: 105505 COMPOSANTS DE CABLAGE : BORNES DE JONCTION | I26: J | J26: EA | K26: EA | L26: NON | P26: ESTREES | R26: 086954 | S26: 46279 | U26: FALSE | AA26: DEJA CREE - article code 086954, ligne non retraitee.
A27: A | B27: Simon DROULERS | C27: 01/09/2026 | D27: SR085-30-00-04-30002-V100 | E27: Kübler | F27: =LEN(G27) -> 89 | G27: COLLECTEUR TOURNANT ARBRE CREUX Ø30 MM 4 VOIES PUISSANCE 10A/400VAC IP64 VERSION STANDARD | H27: 105505 COMPOSANTS DE CABLAGE : BORNES DE JONCTION | I27: E | J27: EA | K27: EA | L27: NON | M27: ELECMATIC S.A.R.L | N27: 113787 | P27: ESTREES | R27: 086955 | S27: 46279 | U27: FALSE | AA27: DEJA CREE - article code 086955, ligne non retraitee.
A28: A | B28: Simon DROULERS | C28: 01/09/2026 | D28: LA36 120A0000F32A-611G21250ACS000 | E28: Linak | F28: =LEN(G28) -> 90 | G28: VÉRIN ÉLECTRIQUE LINÉAIRE LINAK LA36 24/36V DC ~6800N COURSE VARIABLE AVEC RETOUR POSITION | H28: 141100 PNEUMATIQUE : VERINS | I28: Blancheur J | J28: EA | K28: EA | L28: NON | M28: EAMS INDUSTRIE QUIMPER FR 29 | N28: 6906 | P28: ESTREES | R28: 086968 | S28: 46281 | U28: TRUE | AA28: DEJA CREE - article code 086968, ligne non retraitee.
A29: A | B29: Simon DROULERS | C29: 01/09/2026 | D29: 6AV2128-3QB06-0AX1 | E29: SIEMENS | F29: =LEN(G29) -> 57 | G29: PUPITRE TACTILE SIMATIC HMI MTP 1500 15,6 POUCES PROFINET | H29: 105260 AUTOMATISATION : TERMINAUX ET ECRANS | I29: Tête de ligne J | J29: EA | K29: EA | L29: NON | P29: ESTREES | R29: 086896 | S29: 46272 | U29: TRUE | AA29: DEJA CREE - article code 086896, ligne non retraitee.
A30: A | B30: Simon DROULERS | C30: 01/09/2026 | D30: OG5129 | E30: IFM | F30: =LEN(G30) -> 71 | G30: CELLULE BARRAGE PHOTOELECTRIQUE EMETTEUR PORTEE 9M CONNECTEUR M12 24VDC | H30: 105940 DETECTION : DETECTEURS PHOTOELECTRIQUES BARRAGES | I30: Deballeuse de fonds J | J30: EA | K30: EA | L30: NON | M30: IFM ELECTRONIC LE BOURGET DU LAC FR 73 | N30: 5966 | P30: ESTREES | R30: 086890 | S30: 46269 | U30: TRUE | AA30: DEJA CREE - article code 086890, ligne non retraitee.
A31: A | B31: Simon DROULERS | C31: 01/09/2026 | D31: OG5128 | E31: IFM | F31: =LEN(G31) -> 62 | G31: CELLULE BARRAGE PHOTOELECTRIQUE RECEPTEUR CONNECTEUR M12 24VDC | H31: 105940 DETECTION : DETECTEURS PHOTOELECTRIQUES BARRAGES | I31: Deballeuse de fonds J | J31: EA | K31: EA | L31: NON | M31: IFM ELECTRONIC LE BOURGET DU LAC FR 73 | N31: 5966 | P31: ESTREES | R31: 086891 | S31: 46269 | U31: TRUE | AA31: DEJA CREE - article code 086891, ligne non retraitee.
A32: A | B32: Simon DROULERS | C32: 01/09/2026 | D32: IY5048 | E32: IFM | F32: =LEN(G32) -> 70 | G32: DETECTEUR INDUCTIF FILETAGE M5 CONNECTEUR M8 NO PORTEE 1,5MM 24VDC PNP | H32: 105930 DETECTION : DETECTEURS INDUCTIFS FILETES | I32: Deballeuse de fonds J | J32: EA | K32: EA | L32: NON | M32: IFM ELECTRONIC LE BOURGET DU LAC FR 73 | N32: 5966 | P32: ESTREES | R32: OBSOLETE | S32: 46272 | U32: TRUE | AA32: DEJA CREE - article code OBSOLETE, ligne non retraitee.
A33: A | B33: Simon DROULERS | C33: 01/09/2026 | D33: XPSMCMCP0802 | E33: SCHNEIDER | F33: =LEN(G33) -> 71 | G33: MODULE DE SECURITE PREVENTA 8 ENTREES 2 SORTIES CONNECTEUR A VIS 24 VDC | H33: 105755 CONTACTEURS ET RELAIS : RELAIS DE SECURITE | I33: Deballeuse de fonds J | J33: EA | K33: EA | L33: NON | P33: ESTREES | R33: 086902 | S33: 46272 | U33: TRUE | AA33: DEJA CREE - article code 086902, ligne non retraitee.
A34: A | B34: Simon DROULERS | C34: 01/09/2026 | D34: TBL 015-124 | E34: TRACO POWER | F34: =LEN(G34) -> 73 | G34: ALIMENTATION 15W INPUT 0.38- 0.24A 100-240VAC 50/60Hz OUTPOUT 24VDC 0,63A | H34: 105801 CONVERTISSEURS : ALIMENTATIONS CONTINUES | J34: EA | K34: EA | L34: NON | M34: RS COMPONENTS BEAUVAIS FR 60 | N34: 5985 | P34: ESTREES | R34: 086956 | S34: 46279 | U34: FALSE | AA34: DEJA CREE - article code 086956, ligne non retraitee.
A35: A | B35: Simon DROULERS | C35: 01/09/2026 | D35: SR15-KT32X1-S316-LT | E35: ELECTRIX | F35: =LEN(G35) -> 74 | G35: INTERRUPTEUR SECTIONNEUR WASHDOWN PRO 32A TRIPHASE TOIT INCLINE INOX IP69K | H35: 106460 PROTECTION ET COUPURE : INTERRUPTEURS SECTIONNEURS | J35: EA | K35: EA | L35: NON | M35: ELECTRIX INTERNATIONAL CO.DURHAM GB 00 | N35: 11783 | P35: ESTREES | R35: 086957 | S35: 46279 | U35: FALSE | AA35: DEJA CREE - article code 086957, ligne non retraitee.
A36: A | B36: Simon DROULERS | C36: 01/09/2026 | D36: KT KU AUX 1NO 1NC | E36: ELECTRIX | F36: =LEN(G36) -> 61 | G36: CONTACT AUXILIAIRE INTERRUPTEUR SECTIONNEUR 1NO 1NC KU SERIES | H36: 105715 CONTACTEURS ET RELAIS : CONTACTEURS AUXILIAIRES | J36: EA | K36: EA | L36: NON | M36: ELECTRIX INTERNATIONAL CO.DURHAM GB 00 | N36: 11783 | P36: ESTREES | R36: 086958 | S36: 46279 | U36: FALSE | AA36: DEJA CREE - article code 086958, ligne non retraitee.
A37: A | B37: Simon DROULERS | C37: 01/09/2026 | D37: KM1-UCRR-D-E | E37: ASCON | F37: =LEN(G37) -> 76 | G37: REGULATEUR 48X48 ENTREE UNIV - SORT PRINC RELAIS - 1 SORTIE ALARME 24-240VAC | H37: 106255 MESURE ET REGULATION : REGULATEURS ET CONVERTISSEURS | J37: EA | K37: EA | L37: NON | M37: ELECMATIC S.A.R.L | N37: 113787 | P37: ESTREES | R37: 086193 | T37: Doublon avec l'article 086193 (REGULATEUR 48X48 ENTREE UNIV - SORT PRINC RELAIS - 1 SORTIE ALARME 24-240VAC). Demande non creee. | U37: FALSE | AA37: DEJA CREE - article code 086193, ligne non retraitee.
A38: A | B38: Simon DROULERS | C38: 01/09/2026 | D38: KM3-UCIRRD-E | E38: ASCON | F38: =LEN(G38) -> 79 | G38: REGULATEUR 48X48 ENTREE UNIV - SORT PRINC 4/20MA - 2 SORTIES ALARMES 24-240 VAC | H38: 106255 MESURE ET REGULATION : REGULATEURS ET CONVERTISSEURS | J38: EA | K38: EA | L38: NON | M38: ELECMATIC S.A.R.L | N38: 113787 | P38: ESTREES | R38: 086194 | T38: Doublon avec l'article 086194 (REGULATEUR 48X48 ENTREE UNIV - SORT PRINC 4/20MA - 2 SORTIES ALARMES 24-240 VAC). Demande non creee. | U38: FALSE | AA38: DEJA CREE - article code 086194, ligne non retraitee.
A39: A | B39: Simon DROULERS | C39: 01/09/2026 | D39: 9933-05-101 | E39: PARKER | F39: =LEN(G39) -> 49 | G39: FILTRE ADSORBANT EN LIGNE JETABLE SILICE GEL 1/4" | H39: 140700 PNEUMATIQUE : FILTRES | J39: EA | K39: EA | L39: NON | P39: ESTREES | R39: 086925 | S39: 46273 | U39: TRUE | AA39: DEJA CREE - article code 086925, ligne non retraitee.
A40: A | B40: Simon DROULERS | C40: 01/09/2026 | D40: 9900-05-BK | E40: PARKER | F40: =LEN(G40) -> 50 | G40: CARTOUCHE FILTRE EN LIGNE ADSORBANT SILICE GEL 1/4 | H40: 140700 PNEUMATIQUE : FILTRES | J40: EA | K40: EA | L40: NON | P40: ESTREES | R40: 086940 | S40: 46274 | U40: TRUE | AA40: DEJA CREE - article code 086940, ligne non retraitee.
...

Sheet Classe B - Article générique
A1: Version du 31/08/2026​ | B1: A remplir par le demandeur | C1: A remplir par le demandeur | D1: A remplir par le demandeur | E1: A remplir par la Cellule Référentielle | F1: Ne pas modifier | G1: A remplir par le demandeur | H1: A remplir par le demandeur (menu déroulant) | I1: A remplir par le demandeur | J1: A remplir par le demandeur | K1: A remplir par le demandeur | L1: A remplir par le demandeur | M1: A remplir par le demandeur | N1: A remplir par le demandeur | O1: A remplir par le demandeur | P1: A remplir par le demandeur (menu déroulant) | Q1: A remplir par le demandeur | R1: A remplir par la Cellule Référentielle | S1: A remplir par la Cellule Référentielle | T1: A remplir par la Cellule Référentielle | U1: Ajouté par le contrôle automatique — les colonnes d'origine ne sont jamais modifiées
A2: Classe Article | B2: Demandeur | C2: Date Demande | D2: Référence Fabricant / Générique | E2: Marque | F2: Check long. Désign. | G2: Désignation | H2: Famille | I2: Spécifique pour machine | J2: Unité Stock | K2: Unité Commande | L2: Certificat d'alimentarité? | M2: Fournisseur (nom) | N2: Fournisseur (code) | O2: Référence Fournisseur | P2: Site | Q2: Remarques demandeur | R2: Code Article | S2: Date de création | T2: Remarque Cellule Référentielle | U2: Référence constructeur confirmée | V2: Marque confirmée | W2: Fournisseur confirmé | X2: Référence fournisseur confirmée | Y2: Statut réf. / marque | Z2: Désignation IA 1 (constructeur) | AA2: Justification IA 1 | AB2: Désignation IA 2 (variante base article) | AC2: Justification IA 2 | AD2: Désignation algorithme | AE2: Justification algorithme | AF2: Article déjà existant (base) | AG2: Photo produit 1 (lien) | AH2: Photo produit 2 (lien) | AI2: Photo produit 3 (lien) | AJ2: Niveau photo | AK2: Fiche technique (lien) | AL2: Page constructeur (lien) | AM2: Page distributeur (lien) | AN2: Indice de confiance | AO2: Justification du contrôle | AP2: Famille corrigée | AQ2: Contrôle famille | AR2: Spécifique machine corrigé | AS2: Contrôle machine
A3: B | B3: Vincent DARTHOS | C3: 46267 | D3: VIS INOX TFF M10x100 | E3: Générique | F3: =LEN(G3) -> 45 | G3: VIS A TETE FRAISEE FENDUE INOX M10X100 DIN963 | H3: 155910 : VISSERIE FIXATION : VIS ECROUS : INOX | J3: EA | K3: EA | L3: Non | M3: INTER INOX | N3: 6663 | O3: VIS INOX TFF M10x100 | P3: BORDERES | Q3: Merci ! | R3: 086923 | S3: 46273 | Y3: DEJA CREE - article code 086923, ligne non retraitee.
A4: B | B4: Vincent DARTHOS | C4: 46267 | D4: VIS INOX TFF M6x80 | E4: Générique | F4: =LEN(G4) -> 43 | G4: VIS A TETE FRAISEE FENDUE INOX M6X80 DIN963 | H4: 155910 : VISSERIE FIXATION : VIS ECROUS : INOX | J4: EA | K4: EA | L4: Non | M4: INTER INOX | N4: 6663 | O4: VIS INOX TFF M6x80 | P4: BORDERES | Q4: Merci ! | R4: 086924 | S4: 46273 | Y4: DEJA CREE - article code 086924, ligne non retraitee.
A5: B | B5: Vincent DARTHOS | C5: 46267 | D5: VIS INOX TFF M6x70 | E5: Générique | F5: =LEN(G5) -> 43 | G5: VIS A TETE FRAISEE FENDUE INOX M6X70 DIN963 | H5: 155910 : VISSERIE FIXATION : VIS ECROUS : INOX | J5: EA | K5: EA | L5: Non | M5: INTER INOX | N5: 6663 | O5: VIS INOX TFF M6x70 | P5: BORDERES | Q5: Merci ! | R5: 086926 | S5: 46273 | Y5: DEJA CREE - article code 086926, ligne non retraitee.
A6: B | B6: Vincent DARTHOS | C6: 46267 | D6: VIS INOX POELIER FENDUE M8x25 | E6: Générique | F6: =LEN(G6) -> 39 | G6: VIS A METAUX POELIER FENDUES INOX M8X25 | H6: 155910 : VISSERIE FIXATION : VIS ECROUS : INOX | J6: EA | K6: EA | L6: Non | M6: INTER INOX | N6: 6663 | O6: VIS INOX POELIER FENDUE M8x25 | P6: BORDERES | Q6: Merci ! | R6: 086927 | S6: 46273 | Y6: DEJA CREE - article code 086927, ligne non retraitee.
A7: B | B7: Vincent DARTHOS | C7: 46267 | D7: VIS INOX POELIER FENDUE M10x25 | E7: Générique | F7: =LEN(G7) -> 40 | G7: VIS A METAUX POELIER FENDUES INOX M10X25 | H7: 155910 : VISSERIE FIXATION : VIS ECROUS : INOX | J7: EA | K7: EA | L7: Non | M7: INTER INOX | N7: 6663 | O7: VIS INOX POELIER FENDUE M10x25 | P7: BORDERES | Q7: Merci ! | R7: 086949 | S7: 46275 | Y7: DEJA CREE - article code 086949, ligne non retraitee.
A8: B | B8: Vincent DARTHOS | C8: 46267 | D8: VIS INOX POELIER FENDUE M10x30 | E8: Générique | F8: =LEN(G8) -> 40 | G8: VIS A METAUX POELIER FENDUES INOX M10X30 | H8: 155910 : VISSERIE FIXATION : VIS ECROUS : INOX | J8: EA | K8: EA | L8: Non | M8: INTER INOX | N8: 6663 | O8: VIS INOX POELIER FENDUE M10x30 | P8: BORDERES | Q8: Merci ! | R8: 086947 | S8: 46275 | Y8: DEJA CREE - article code 086947, ligne non retraitee.
A9: B | B9: Vincent DARTHOS | C9: 46267 | D9: VIS INOX TH P FILE M24x160 | E9: Générique | F9: =LEN(G9) -> 74 | G9: VIS TETE HEXAGONALE SANS EMPREINTE FILETAGE PARTIEL - TH INOX A2 24X160 MM | H9: 155910 : VISSERIE FIXATION : VIS ECROUS : INOX | J9: EA | K9: EA | L9: Non | M9: INTER INOX | N9: 6663 | O9: VIS INOX TH P FILE M24x160 | P9: BORDERES | Q9: Merci ! | R9: 086970 | S9: 46281 | Y9: DEJA CREE - article code 086970, ligne non retraitee.
A10: B | B10: Vincent DARTHOS | C10: 46267 | D10: VIS INOX TH M14x20 | E10: Générique | F10: =LEN(G10) -> 77 | G10: VIS TETE HEXAGONALE SANS EMPREINTE ENTIEREMENT FILETEE - TH INOX A2 M14X20 MM | H10: 155910 : VISSERIE FIXATION : VIS ECROUS : INOX | J10: EA | K10: EA | L10: Non | M10: INTER INOX | N10: 6663 | O10: VIS INOX TH M14x20 | P10: BORDERES | Q10: Merci ! | R10: 086951 | S10: 46275 | Y10: DEJA CREE - article code 086951, ligne non retraitee.
A11: B | B11: Vincent DARTHOS | C11: 46267 | D11: VIS INOX TFHC M3x8 | E11: Générique | F11: =LEN(G11) -> 56 | G11: VIS TETE FRAISEE SIX PANS CREUX TFHC DIN 7991 A2 M3X8 MM | H11: 155910 : VISSERIE FIXATION : VIS ECROUS : INOX | J11: EA | K11: EA | L11: Non | M11: INTER INOX | N11: 6663 | O11: VIS INOX TFHC M3x8 | P11: BORDERES | Q11: Merci ! | R11: 086971 | S11: 46281 | Y11: DEJA CREE - article code 086971, ligne non retraitee.
A12: B | B12: Vincent DARTHOS | C12: 46267 | D12: VIS INOX TFHC M5x16 | E12: Générique | F12: =LEN(G12) -> 57 | G12: VIS TETE FRAISEE SIX PANS CREUX TFHC DIN 7991 A2 M5X16 MM | H12: 155910 : VISSERIE FIXATION : VIS ECROUS : INOX | J12: EA | K12: EA | L12: Non | M12: INTER INOX | N12: 6663 | O12: VIS INOX TFHC M5x16 | P12: BORDERES | Q12: Merci ! | R12: 086972 | S12: 46281 | Y12: DEJA CREE - article code 086972, ligne non retraitee.
A13: B | B13: Vincent DARTHOS | C13: 46267 | D13: VIS INOX TCHC M3x30 | E13: Générique | F13: =LEN(G13) -> 59 | G13: VIS TETE CYLINDRIQUE HEXAGONALE CREUSE DIN933 INOX A2 M3X30 | H13: 155910 : VISSERIE FIXATION : VIS ECROUS : INOX | J13: EA | K13: EA | L13: Non | M13: INTER INOX | N13: 6663 | O13: VIS INOX TCHC M3x30 | P13: BORDERES | Q13: Merci ! | R13: 086974 | S13: 46281 | Y13: DEJA CREE - article code 086974, ligne non retraitee.
A14: B | B14: Vincent DARTHOS | C14: 46267 | D14: ECROU INOX HEX M3 | E14: Générique | F14: =LEN(G14) -> 34 | G14: ECROU HEXAGONAL M3 A2 DIN 934 INOX | H14: 155910 : VISSERIE FIXATION : VIS ECROUS : INOX | J14: EA | K14: EA | L14: Non | M14: INTER INOX | N14: 6663 | O14: ECROU INOX HEX M3 | P14: BORDERES | Q14: Merci ! | R14: 086975 | S14: 46281 | Y14: DEJA CREE - article code 086975, ligne non retraitee.
... A21: B | B21: Vincent DARTHOS | C21: 46267 | D21: GOUPILLE I 2,5X14 | E21: Générique | F21: =LEN(G21) -> 44 | G21: GOUPILLES FENDUES INOX DIAMETRE 2,5X14 DIN94 | H21: 155300 : VISSERIE FIXATION : GOUPILLES | J21: EA | K21: EA | L21: Non | M21: INTER INOX | N21: 6663 | O21: GOUPILLE I 2,5X14 | P21: BORDERES | Q21: Merci ! | R21: 086920 | S21: 46273 | Y21: DEJA CREE - article code 086920, ligne non retraitee.
A22: B | B22: Vincent DARTHOS | C22: 46275 | D22: ENG.38/M3/022 | E22: Générique | F22: =LEN(G22) -> 32 | G22: ENGRENAGE MOD 3 22 DTS 38/M3/022 | H22: 150101 ACCOUPLEMENTS / TRANSMISSION : ACCOUPLEMENTS | J22: EA | K22: EA | L22: Non | M22: SAFIM | N22: 27358 | O22: ENG.38/M3/022 | P22: BORDERES | W22: SAFIM | Y22: Non confirmé - aucune source publique trouvée ; VALIDER - CHAMPS NON CONFIRMES | AA22: VIDE : aucun libellé officiel constructeur de la variante exacte n est confirmé. Une série, une société ou un libellé de distributeur ne remplace pas cette preuve. | AB22: ARTICLE A IDENTIFIER - REFERENCE ENG.38/M3/022 | AC22: Proposition transparente, non validée : aucune nature produit de cette référence n est suffisamment prouvée par une source officielle/distributeur fiable ou une correspondance de base contextualisée. La saisie brute n est pas présentée comme vérifiée. | AD22: ENGRENAGE MOD 3 22 DENTS 38/M3/022 | AE22: Saisie d origine uniquement, majuscules/espacement d unités et traduction usuelle sans ajout de caractéristiques. Nature source ENGRENAGE déjà présente : 5/317 codes distincts, soit 1.6%. Conservée même minoritaire. Dominante ACCOUPLEMENT : 96/317, soit 30.3% ; seuil d éligibilité 30 %, jamais une validation technique. | AJ22: Aucune photo trouvée | AN22: Faible | AO22: Les recherches exactes et normalisées d’ENG.38/M3/022 n’identifient aucun fabricant, le seul résultat voisin Lufra 38/M3/076 n’étant pas une preuve pour 022, tandis que la fiche Cylex atteste seulement le fournisseur français SAFIM. Photo : Aucune URL d’image éditeur exploitable n’a été renvoyée par les pages consultées. | AQ22: VALIDER - CODE FAMILLE VALIDE DANS LE REFERENTIEL ; adéquation technique non confirmée faute de nature sourcée. | AS22: Champ vide conservé ; aucune machine inventée pour ce composant de commerce.
A23: B | B23: Vincent DARTHOS | C23: 46282 | D23: GOUPILLE I 5X40 | E23: Générique | F23: 44 | G23: GOUPILLES FENDUES INOX DIAMETRE 5X40 4 DIN94 | H23: 155300 : VISSERIE FIXATION : GOUPILLES | J23: EA | K23: EA | L23: Non | M23: INTER INOX | N23: 6663 | O23: GOUPILLE I 5X40 | P23: BORDERES | Q23: Merci ! | R23: 087066 | S23: 46287 | Y23: DEJA CREE - article code 087066, ligne non retraitee.
A24: B | B24: Vincent DARTHOS | C24: 46282 | D24: VIS INOX TFF 3X30 | E24: Générique | F24: 59 | G24: VIS A TETE FRAISEE FENDUE INOX M3X30 | H24: 155910 : VISSERIE FIXATION : VIS ECROUS : INOX | J24: EA | K24: EA | L24: Non | M24: INTER INOX | N24: 6663 | O24: VIS INOX TFF 3X30 | P24: BORDERES | Q24: Merci ! | R24: 087070 | S24: 46287 | Y24: DEJA CREE - article code 087070, ligne non retraitee.
A25: B | B25: Vincent DARTHOS | C25: 46284 | D25: 61912 2RS | E25: Générique | F25: =LEN(G25) -> 18 | G25: ROULEMENT 60X85X13 | H25: 150800 ROULEMENTS | J25: EA | K25: EA | L25: Non | M25: CIR | N25: 92179 | O25: 61912 2RS | P25: BORDERES | Q25: Merci ! | R25: 087201 | S25: 46293 | Y25: DEJA CREE - article code 087201, ligne non retraitee.
A26: B | B26: Vincent DARTHOS | C26: 46287 | D26: ADN-25-60-A-P-A | E26: Générique | F26: =LEN(G26) -> 29 | G26: VERIN COMPACT ADN-25-60-A-P-A | H26: 141100 PNEUMATIQUE : VERINS | J26: EA | K26: EA | L26: Non | M26: FESTO | N26: 14436 | O26: 536373 | P26: BORDERES | Q26: Ok, fait | T26: Marque et référence FESTO, non générique. Merci de déplacer cet article en classe A | U26: ADN-25-60-A-P-A | V26: Festo | W26: Festo E.U.R.L. | X26: 536373 | Y26: Référence et marque confirmées (constructeur) | Z26: VÉRIN COMPACT | AA26: Reformulation française du libellé constructeur de la référence vérifiée. Source : Festo — ADN-25-60-A-P-A — Part number 536373; Festo — Compact cylinder ADN-25-60-A-P-A | AB26: VERIN COMPACT DOUBLE EFFET D 25 MM COURSE 60 MM ISO 21287 AMORTISSEMENT ELASTIQUE | AC26: Termes techniques issus exclusivement des sources vérifiées du 07/10/2026, reformulés selon l usage de la famille. Sources : Festo — ADN-25-60-A-P-A — Part number 536373; Festo — Compact cylinder ADN-25-60-A-P-A; Festo France — Mentions légales — Festo E.U.R.L. | AD26: VERIN COMPACT ADN-25-60-A-P-A | AE26: Saisie d origine uniquement, majuscules/espacement d unités et traduction usuelle sans ajout de caractéristiques. Nature source VERIN déjà présente : 742/1018 codes distincts, soit 72.9%. Conservée même minoritaire. Dominante VERIN : 742/1018, soit 72.9% ; seuil d éligibilité 30 %, jamais une validation technique. | AJ26: Aucune photo trouvée | AK26: =HYPERLINK("https://ftp.festo.com/Public/PNEUMATIC/SOFTWARE_SERVICE/Datasheet/EN_US/536373.pdf","https://ftp.festo.com/Public/PNEUMATIC/SOFTWARE_SERVICE/Datasheet/EN_US/536373.pdf") -> https://ftp.festo.com/Public/PNEUMATIC/SOFTWARE_SERVICE/Datasheet/EN_US/536373.pdf | AL26: =HYPERLINK("https://www.festo.com/no/en/a/536373","https://www.festo.com/no/en/a/536373") -> https://www.festo.com/no/en/a/536373 | AN26: Élevé | AO26: La fiche et la page Festo associent ADN-25-60-A-P-A au n° 536373 avec diamètre 25 mm et course 60 mm, et les mentions légales vérifient Festo E.U.R.L. Photo : Les sorties de consultation des pages consultées fournissent du texte sans URL d’image éditeur pleine résolution vérifiable ; aucune image retenue. | AQ26: Code et libellé présents au référentiel source ; nature documentée, configuration exacte restant à contrôler si la preuve est de série. | AS26: Champ vide conservé ; aucune machine inventée pour ce composant de commerce.
A27: B | B27: Alexis DELEAU | C27: 46287 | D27: 51060.080.016 | E27: Générique | F27: =LEN(G27) -> 51 | G27: VIS TETE FRAISEE 6 PANS CREUX M8X16 DIN7991 INOX A2 | H27: 155910 VISSERIE FIXATION : VIS ECROUS : INOX | J27: EA | K27: EA | L27: Non | M27: FABORY | N27: 17436 | O27: 51060.080.016 | P27: ESTREES | Q27: Demande transférée de l'ancien tableau visserie fixation | R27: 087173 | S27: 46293 | Y27: DEJA CREE - article code 087173, ligne non retraitee.
A28: B | B28: Alexis DELEAU | C28: 46287 | D28: 51040.060.012 | E28: Générique | F28: =LEN(G28) -> 77 | G28: VIS A TETE CYLINDRIQUE A SIX PANS CREUX AVEC TETE BASSE DIN7984 INOX A2 M6X12 | H28: 155910 VISSERIE FIXATION : VIS ECROUS : INOX | J28: EA | K28: EA | L28: Non | M28: FABORY | N28: 17436 | O28: 51040.060.012 | P28: ESTREES | Q28: Demande transférée de l'ancien tableau visserie fixation | R28: 087176 | S28: 46293 | Y28: DEJA CREE - article code 087176, ligne non retraitee.
A29: B | B29: Alexis DELEAU | C29: 46287 | D29: 51040.080.016 | E29: Générique | F29: =LEN(G29) -> 77 | G29: VIS A TETE CYLINDRIQUE A SIX PANS CREUX AVEC TETE BASSE DIN7984 INOX A2 M8X16 | H29: 155910 VISSERIE FIXATION : VIS ECROUS : INOX | J29: EA | K29: EA | L29: Non | M29: FABORY | N29: 17436 | O29: 51040.080.016 | P29: ESTREES | Q29: Demande transférée de l'ancien tableau visserie fixation | R29: 087178 | S29: 46293 | Y29: DEJA CREE - article code 087178, ligne non retraitee.
A30: B | B30: Alexis DELEAU | C30: 46287 | D30: 51050.050.012 | E30: Générique | F30: =LEN(G30) -> 61 | G30: VIS A TETE CYLINDRIQUE HEXAGONALE CREUSE INOX A2 DIN912 M5X12 | H30: 155910 VISSERIE FIXATION : VIS ECROUS : INOX | J30: EA | K30: EA | L30: Non | M30: FABORY | N30: 17436 | O30: 51050.050.012 | P30: ESTREES | Q30: Demande transférée de l'ancien tableau visserie fixation | R30: 87180 | S30: 46293 | Y30: DEJA CREE - article code 87180, ligne non retraitee.
A31: B | B31: Vincent DARTHOS | C31: 46290 | D31: MCHMS5-SS-21-DC-LQD | E31: Générique | F31: =LEN(G31) -> 47 | G31: INTERUPTEUR DE SECURITE MAGNETIQUE SANS CONTACT | H31: 105755 CONTACTEURS ET RELAIS : RELAIS DE SECURITE | J31: EA | K31: EA | L31: Non | M31: ELEC SUD OUEST | N31: 89122 | O31: MCHMS5-SS-21-DC-LQD | P31: BORDERES | Q31: Ok, fait | T31: Marque et référence MECHAN-CONTROLS, non générique. Merci de déplacer cet article en classe A | W31: ELEC SUD OUEST | Y31: Série/gamme confirmée - configuration exacte non confirmée ; VALIDER - CHAMPS NON CONFIRMES | AA31: VIDE : aucun libellé officiel constructeur de la variante exacte n est confirmé. Une série, une société ou un libellé de distributeur ne remplace pas cette preuve. | AB31: INTERRUPTEUR SECURITE MAGNETIQUE SERIE MS5 SSLQD INOX 316 - COMPOSITION A VALIDER | AC31: Termes techniques issus exclusivement des sources vérifiées du 07/10/2026, reformulés selon l usage de la famille. Portée limitée à la série : cette proposition ne valide pas la variante ni les détails de saisie exclus des sources. Sources : Mechan Controls — MS5SSLQD — MS5-SS-21-DC-LQD; Machinesafety-Shop — MS5-SS-21-DC-LQD — Magnetic safety sensor; Annuaire des Entreprises — ELEC SUD OUEST — SIREN 441395712 | AD31: INTERRUPTEUR DE SECURITE MAGNETIQUE SANS CONTACT | AE31: Saisie d origine uniquement, majuscules/espacement d unités et traduction usuelle sans ajout de caractéristiques. Nature source conservée sans substitution sémantique : 226 codes distincts de famille. Dominante RELAIS : 94/226, soit 41.6% ; seuil d éligibilité 30 %, jamais une validation technique. | AJ31: Aucune photo trouvée | AL31: =HYPERLINK("https://www.mechancontrols.com/products/magnasafe/ms5sslqd/","https://www.mechancontrols.com/products/magnasafe/ms5sslqd/") -> https://www.mechancontrols.com/products/magnasafe/ms5sslqd/ | AM31: =HYPERLINK("https://machinesafety-shop.com/ms5-ss-21-dc-lqd-ms5-stainless-steel-magnetic-safety-sensor/","https://machinesafety-shop.com/ms5-ss-21-dc-lqd-ms5-stainless-steel-magnetic-safety-sensor/") -> https://machinesafety-shop.com/ms5-ss-21-dc-lqd-ms5-stainless-steel-magnetic-safety-sensor/ | AN31: Faible | AO31: Mechan Controls et Machinesafety-Shop publient MS5-SS-21-DC-LQD mais aucune source ne relie le préfixe MCH du code saisi à cette référence, et l’Annuaire des Entreprises confirme ELEC SUD OUEST sans code article publié. La marque est laissée non confirmée : les sources identifient une société ou une série, pas le fabricant de la variante demandée. Photo : Les sorties de consultation des pages consultées fournissent du texte sans URL d’image éditeur pleine résolution vérifiable ; aucune image retenue. | AQ31: Code et libellé présents au référentiel source ; nature documentée, configuration exacte restant à contrôler si la preuve est de série. | AS31: Champ vide conservé ; aucune machine inventée pour ce composant de commerce.
A32: B | B32: Nicolas SENS | C32: 46293 | D32: CLAVETTE 8x7x35 DIN6885 | E32: Générique | F32: =LEN(G32) -> 23 | G32: CLAVETTE 8x7x35 DIN6885 | H32: 106300 OUTILLAGE / CONSOMMABLES | J32: EA | K32: EA | L32: Non | M32: MICHAUD CHAILLY LYON FR 69 | N32: 6775 | O32: CLAVETTE 8x7x35 DIN6885 | P32: ESTREES | R32: 087206 | S32: 46293 | Y32: DEJA CREE - article code 087206, ligne non retraitee.
A33: B | B33: Nicolas SENS | C33: 46293 | D33: CLAVETTE 6x6x35 DIN6885 | E33: Générique | F33: =LEN(G33) -> 23 | G33: CLAVETTE 6x6x35 DIN6885 | H33: 106300 OUTILLAGE / CONSOMMABLES | J33: EA | K33: EA | L33: Non | M33: MICHAUD CHAILLY LYON FR 69 | N33: 6775 | O33: CLAVETTE 6x6x35 DIN6885 | P33: ESTREES | R33: 087071 | S33: 46293 | Y33: DEJA CREE - article code 087071, ligne non retraitee.
A34: B | B34: Fabrice BERANGER | C34: 46335 | D34: CAU-14104 | E34: Générique | F34: =LEN(G34) -> 28 | G34: BAGUE PA6 G NAT Ø60X18 HT 65 | H34: 100620 CONVOYAGE A CHAINES : FIXATION ET SUPPORTS | J34: EA | K34: EA | L34: Non | M34: CAUWET | N34: 145648 | O34: CAU-14104 | P34: VAULX VRAUCOURT | W34: JM CAUWET | Y34: Non confirmé - aucune source publique trouvée ; VALIDER - CHAMPS NON CONFIRMES | AA34: VIDE : aucun libellé officiel constructeur de la variante exacte n est confirmé. Une série, une société ou un libellé de distributeur ne remplace pas cette preuve. | AB34: ARTICLE A IDENTIFIER - REFERENCE CAU-14104 | AC34: Proposition transparente, non validée : aucune nature produit de cette référence n est suffisamment prouvée par une source officielle/distributeur fiable ou une correspondance de base contextualisée. La saisie brute n est pas présentée comme vérifiée. | AD34: BAGUE PA6 G NAT Ø60X18 HT 65 | AE34: Saisie d origine uniquement, majuscules/espacement d unités et traduction usuelle sans ajout de caractéristiques. Nature source conservée sans substitution sémantique : 14 codes distincts de famille. Dominante PALIER : 3/14, soit 21.4% ; seuil d éligibilité 30 %, jamais une validation technique. | AJ34: Aucune photo trouvée | AL34: =HYPERLINK("https://www.plastique-cauwet.com/Usinage-plastique/","https://www.plastique-cauwet.com/Usinage-plastique/") -> https://www.plastique-cauwet.com/Usinage-plastique/ | AN34: Faible | AO34: Le site JM CAUWET confirme le fournisseur et son activité d’usinage plastique sur mesure, mais les recherches de CAU-14104/CAU14104 ne publient pas cette bague, son fabricant ni un plan, donc aucune référence catalogue ou fabrication sur plan n’est affirmée. Photo : Code non publié et aucune fiche produit trouvée : aucune URL d’image exacte disponible ; l’activité sur mesure du fournisseur ne prouve pas à elle seule un plan pour cette pièce. | AQ34: VALIDER - CODE FAMILLE VALIDE DANS LE REFERENTIEL ; adéquation technique non confirmée faute de nature sourcée. | AS34: Champ vide conservé ; aucune machine inventée pour ce composant de commerce.
A35: B | B35: Fabrice BERANGER | C35: 14/09/2026 | D35: 32616 | E35: Générique | F35: =LEN(G35) -> 96 | G35: TAPIS SERIE 900 FLUSH GRID(SURFACE AJOUREE)ACETAL BLEU LARGEUR:446MM LONGUEUR 6 METRES 219 RANGS | H35: 101100 CONVOYAGE A TAPIS A PALETTES | J35: EA | K35: EA | L35: Non | M35: INTRALOX | N35: 144465 | O35: 32616 | P35: VAULX VRAUCOURT | W35: Intralox | Y35: Série/gamme confirmée - configuration exacte non confirmée ; VALIDER - CHAMPS NON CONFIRMES | AA35: VIDE : aucun libellé officiel constructeur de la variante exacte n est confirmé. Une série, une société ou un libellé de distributeur ne remplace pas cette preuve. | AB35: TAPIS MODULAIRE SERIE 900 FLUSH GRID PAS 27,2 MM - MATIERE ET CONFECTION A VALIDER | AC35: Termes techniques issus exclusivement des sources vérifiées du 07/10/2026, reformulés selon l usage de la famille. Portée limitée à la série : cette proposition ne valide pas la variante ni les détails de saisie exclus des sources. Sources : Intralox — Series 900 Flush Grid | AD35: TAPIS SERIE 900 FLUSH GRID(SURFACE AJOUREE)ACETAL BLEU LARGEUR:446 MM LONGUEUR 6 METRES 219 RANGS | AE35: Saisie d origine uniquement, majuscules/espacement d unités et traduction usuelle sans ajout de caractéristiques. Nature source TAPIS déjà présente : 88/109 codes distincts, soit 80.7%. Conservée même minoritaire. Dominante TAPIS : 88/109, soit 80.7% ; seuil d éligibilité 30 %, jamais une validation technique. | AJ35: Aucune photo trouvée | AL35: =HYPERLINK("https://www.intralox.com/belt-finder/modular-plastic-belting/series-900/flush-grid","https://www.intralox.com/belt-finder/modular-plastic-belting/series-900/flush-grid") -> https://www.intralox.com/belt-finder/modular-plastic-belting/series-900/flush-grid | AN35: Faible | AO35: La page Intralox Series 900 Flush Grid confirme cette famille et son pas de 27,2 mm, mais ni le numéro 32616 ni la confection acétal bleu 446 mm × 6 m n’ont été trouvés publiquement. La marque est laissée non confirmée : les sources identifient une société ou une série, pas le fabricant de la variante demandée. Photo : Confection de tapis : absence normale de photo exacte ; aucune URL d’image éditeur renvoyée par la page de série. | AP35: 100410 CONVOYAGE A BANDES PLASTIQUES : BANDES | AQ35: VALIDER - FAMILLE PROPOSEE : Nature tapis modulaire plastique de la série 900 documentée ; code 32616 et confection non confirmés. | AS35: Champ vide conservé ; aucune machine inventée pour ce composant de commerce.
